# 스터디 3주차 3문제

### Question 1. 이 코드의 실행 결과는 ?

```java
interface Soundable {
    String getDescription();

    default String toString(){
        return getDescription();
    }
}

abstract class Animal implements Soundable{
    private String sound;

    public Animal(String sound) {
        this.sound = sound;
    }

    public String getSound() {
        return sound;
    }
}

class Cat extends Animal{
    public Cat(String sound) {
        super(sound);
    }

    @Override
    public String getDescription() {
        return "Cat sounds " + getSound();
    }
}

public class Zoo {
    public static void main(String[] args) {
        Animal animal = new Cat("Meow");
        System.out.println(animal);
    }
}
```

1. Cat sounds Meow
2. Cat@404b9385
3. Animal@4554617c
4. 컴파일 에러 발생

### Answer 1.

정답은 4

인터페이스 내에 toString() 메소드를 default 메소드로 선언할 수 없다.

Object 클래스의 기본 메소드들은 모든 객체에 대한 공통의 구현을 제공하는데, 인터페이스에서 이러한 메소드들을 default로 재정의하려고 하면 어떤 메소드 구현을 사용해야 할지 모호성이 생겨 자바에서 금지시키고 있다.

인터페이스 대신 Animal이나 Cat에 toString 오버라이딩을 구현해서 정상적으로 우리가 원하는 값인 Cat sounds Meow를 출력할 수 있다.

### Question 2. 이 코드의 실행 결과는 ?

```java
public class ExceptionTest {
    public static void main(String[] args) {
        try {
            System.out.println("try 실행");
            throw new RuntimeException("예외 발생!");
        } catch (Exception e) {
		        System.out.println(e.getMessage());
            System.out.println("catch 실행");
            return;
        } finally {
            System.out.println("finally 실행");
        }
        System.out.println("try-catch문 이후 실행");
    }
}
```

### Answer 2.

정답은

try 실행

예외 발생!

catch 실행

finally 실행

이렇게 나온다.

throw new RuntimeException에 의해 런타임 예외가 발생하며, catch문으로 가게 됨.

e.getMessage()에 의해 예외 발생! 이라는 메시지를 받아와서 출력하고, catch 실행 멘트까지 나온 뒤

return문을 실행하기 전에 finally블록이 실행된다.

return문에 의해 마지막 try-catch문 이후 실행은 나오지 않게 된다.

### Question 3. 이 코드의 실행 결과는?

```java
public class DbOperator {
    public void connect() throws SQLException {
        // 데이터베이스에 연결하는 코드
        throw new SQLException("데이터베이스에 연결할 수 없습니다.");
    }

    public void processData() {
        try {
            connect();
        } catch (SQLException e) {
            System.out.println("Log: DB 연결 실패");
            throw new RuntimeException(e);
        } finally {
            System.out.println("DB 연결 시도 완료.");
        }
    }
}

public class Test {
    public static void main(String[] args) {
        try {
            new DbOperator().processData();
        } catch (RuntimeException e) {
            System.out.println("Error: " + e.getCause().getMessage());
        }
    }
}

```

### Answer 3.

Log: DB 연결 실패

DB 연결 시도 완료.

데이터베이스에 연결할 수 없습니다.

순서로 나오게 됨.

connect 메소드를 호출할 때 SQLException이 발생하고, catch에서 로그 메시지 출력 후 RuntimeException으로 포장되어 다시 발생된다.

finally는 예외 여부와 상관 없이 출력되고, main메소드의 catch에서 RuntimeException이 잡혀서 SQLException의 메시지가 출력된다.